Workbook

Sheet Summary
F1: CO2 reduction comparaison marketing-based
F2: =(I14-E14)/E14 -> -0.1419133 | J2: =(M14-E14)/E14 -> 0.10174507 | N2: =(Q14-E14)/E14 -> -0.41352348
B3: ACTUALS BASELINE (BL) | F3: HP | J3: LENOVO | N3: DELL
A4: Profile | B4: Avg PCF | C4: Avg Energy | D4: #Instances | E4: Kg CO2 Est. | F4: Avg PCF | G4: Avg Energy | H4: vs BL | I4: Kg CO2 Est. | J4: Avg PCF | K4: Avg Energy | L4: vs BL | M4: Kg CO2 Est. | N4: Avg PCF | O4: Avg Energy | P4: vs BL | Q4: Kg CO2 Est.
A5: 1 | B5: ='HP Current Models consolidated'!N2 -> 179 | C5: ='HP Current Models consolidated'!O2 -> 16.9 | D5: 83728 | E5: =B5*D5 -> 14987312 | F5: ='New HP Devices'!I2 -> 159 | G5: ='New HP Devices'!J2 -> 18.2 | H5: =(F5-B5)/B5 -> -0.11173184 | I5: =D5*F5 -> 13312752 | J5: ='New Lenovo Devices'!J2 -> 178.5 | K5: ='New Lenovo Devices'!K2 -> 14.54 | L5: =(J5-B5)/B5 -> -0.0027932961 | M5: =D5*J5 -> 14945448 | N5: ='New Dell devices'!K2 -> 107 | O5: ='New Dell devices'!L2 -> 20 | P5: =(N5-B5)/B5 -> -0.40223464 | Q5: =D5*N5 -> 8958896
A6: 2 | B6: ='HP Current Models consolidated'!N3 -> 191 | C6: ='HP Current Models consolidated'!O3 -> 19.9 | D6: 12571 | E6: =B6*D6 -> 2401061 | F6: ='New HP Devices'!I3 -> 156.5 | G6: ='New HP Devices'!J3 -> 18.7 | H6: =(F6-B6)/B6 -> -0.18062827 | I6: =D6*F6 -> 1967361.5 | J6: ='New Lenovo Devices'!J3 -> 192.5 | K6: ='New Lenovo Devices'!K3 -> 14.46 | L6: =(J6-B6)/B6 -> 0.0078534031 | M6: =D6*J6 -> 2419917.5 | N6: ='New Dell devices'!K3 -> 118 | O6: ='New Dell devices'!L3 -> 21.5 | P6: =(N6-B6)/B6 -> -0.38219895 | Q6: =D6*N6 -> 1483378
A7: 3 | B7: ='HP Current Models consolidated'!N4 -> 165 | C7: ='HP Current Models consolidated'!O4 -> 14.7 | D7: 1536 | E7: =B7*D7 -> 253440 | F7: ='New HP Devices'!I4 -> 184 | G7: ='New HP Devices'!J4 -> 20.55 | H7: =(F7-B7)/B7 -> 0.11515152 | I7: =D7*F7 -> 282624 | J7: ='New Lenovo Devices'!J4 -> 176.5 | K7: ='New Lenovo Devices'!K4 -> 14.345 | L7: =(J7-B7)/B7 -> 0.06969697 | M7: =D7*J7 -> 271104 | N7: ='New Dell devices'!K4 -> 104 | O7: ='New Dell devices'!L4 -> 17.7 | P7: =(N7-B7)/B7 -> -0.36969697 | Q7: =D7*N7 -> 159744
A8: 4 | B8: ='HP Current Models consolidated'!N5 -> 265 | C8: ='HP Current Models consolidated'!O5 -> 25.3 | D8: 3168 | E8: =B8*D8 -> 839520 | F8: ='New HP Devices'!I5 -> 245.5 | G8: ='New HP Devices'!J5 -> 22.55 | H8: =(F8-B8)/B8 -> -0.073584906 | I8: =D8*F8 -> 777744 | J8: ='New Lenovo Devices'!J5 -> 260.5 | K8: ='New Lenovo Devices'!K5 -> 21.75 | L8: =(J8-B8)/B8 -> -0.016981132 | M8: =D8*J8 -> 825264 | N8: ='New Dell devices'!K5 -> 118 | O8: ='New Dell devices'!L5 -> 19.3 | P8: =(N8-B8)/B8 -> -0.55471698 | Q8: =D8*N8 -> 373824
A9: 5 | B9: ='HP Current Models consolidated'!N6 -> 122 | C9: ='HP Current Models consolidated'!O6 -> 47.2 | D9: 1715 | E9: =B9*D9 -> 209230 | F9: ='New HP Devices'!I6 -> 188 | G9: ='New HP Devices'!J6 -> 14.6 | H9: =(F9-B9)/B9 -> 0.54098361 | I9: =D9*F9 -> 322420 | J9: ='New Lenovo Devices'!J6 -> 79 | K9: ='New Lenovo Devices'!K6 -> 15.4 | L9: =(J9-B9)/B9 -> -0.35245902 | M9: =D9*J9 -> 135485 | N9: ='New Dell devices'!K6 -> 110 | O9: ='New Dell devices'!L6 -> 17.8 | P9: =(N9-B9)/B9 -> -0.098360656 | Q9: =D9*N9 -> 188650
A10: 6 | B10: ='HP Current Models consolidated'!N7 -> 183 | C10: ='HP Current Models consolidated'!O7 -> 41.5 | D10: 4255 | E10: =B10*D10 -> 778665 | F10: ='New HP Devices'!I7 -> 102 | G10: ='New HP Devices'!J7 -> 11 | H10: =(F10-B10)/B10 -> -0.44262295 | I10: =D10*F10 -> 434010 | J10: ='New Lenovo Devices'!J7 -> 241 | K10: ='New Lenovo Devices'!K7 -> 15.65 | L10: =(J10-B10)/B10 -> 0.31693989 | M10: =D10*J10 -> 1025455 | N10: ='New Dell devices'!K7 -> 107 | O10: ='New Dell devices'!L7 -> 18.5 | P10: =(N10-B10)/B10 -> -0.41530055 | Q10: =D10*N10 -> 455285
A11: 7 | B11: ='HP Current Models consolidated'!N8 -> 250 | C11: ='HP Current Models consolidated'!O8 -> 41 | D11: 10412 | E11: =B11*D11 -> 2603000 | F11: ='New HP Devices'!I8 -> 163.33333 | G11: ='New HP Devices'!J8 -> 55.133333 | H11: =(F11-B11)/B11 -> -0.34666667 | I11: =D11*F11 -> 1700626.7 | J11: ='New Lenovo Devices'!J8 -> 382 | K11: ='New Lenovo Devices'!K8 -> 47.995 | L11: =(J11-B11)/B11 -> 0.528 | M11: =D11*J11 -> 3977384 | N11: ='New Dell devices'!K8 -> 120.3 | O11: ='New Dell devices'!L8 -> 34.85 | P11: =(N11-B11)/B11 -> -0.5188 | Q11: =D11*N11 -> 1252563.6
A12: 8 | B12: ='HP Current Models consolidated'!N9 -> 487 | C12: ='HP Current Models consolidated'!O9 -> 203 | D12: 422 | E12: =B12*D12 -> 205514 | F12: ='New HP Devices'!I9 -> 693 | G12: ='New HP Devices'!J9 -> 309.3 | H12: =(F12-B12)/B12 -> 0.42299795 | I12: =D12*F12 -> 292446 | J12: ='New Lenovo Devices'!J9 -> 2205 | K12: ='New Lenovo Devices'!K9 -> 580.88 | L12: =(J12-B12)/B12 -> 3.5277207 | M12: =D12*J12 -> 930510 | N12: ='New Dell devices'!K9 -> 406 | O12: ='New Dell devices'!L9 -> 175 | P12: =(N12-B12)/B12 -> -0.16632444 | Q12: =D12*N12 -> 171332
A13: 9 | B13: ='HP Current Models consolidated'!N10 -> 0 | C13: ='HP Current Models consolidated'!O10 -> 0 | D13: 175 | E13: =B13*D13 -> 0 | F13: ='New HP Devices'!I10 -> 150 | G13: ='New HP Devices'!J10 -> 14.5 | I13: =D13*F13 -> 26250 | J13: ='New Lenovo Devices'!J10 -> 79 | K13: ='New Lenovo Devices'!K10 -> 15.4 | M13: =D13*J13 -> 13825 | N13: ='New Dell devices'!K10 -> 124 | O13: ='New Dell devices'!L10 -> 21.2 | Q13: =D13*N13 -> 21700
E14: =SUM(E5:E13) -> 22277742 | H14: =AVERAGE(H5:H12) -> -0.0095126963 | I14: =SUM(I5:I13) -> 19116234 | L14: =AVERAGE(L5:L12) -> 0.50974719 | M14: =SUM(M5:M13) -> 24544392 | P14: =AVERAGE(P5:P12) -> -0.36345415 | Q14: =SUM(Q5:Q13) -> 13065373
A16: Disclaimers
B17: - Scope: Focused on high-volume models (Top 20% / Pareto). - Data Source: Based on vendor marketing data; subject to methodology variances. - Time Horizon: Projections follow the 2030 replacement roadmap. - Exclusions: Logistics (Air/Sea), packaging, and circularity (refurbishment) are not factored in. - Green Energy: Focuses on Embodied Carbon (PCF), assuming 100% renewable energy at Roche sites.
B20: Original file: https://drive.google.com/file/d/16ioOSHzJyJsb51nWzuKOZfGUjor8L6vu/view
B21: Confidential info

Sheet HP Current Models consolidated
A1: Profile | B1: Original Model | C1: Mapped to HP naming convention | D1: CO2 Emission (Kg CO2) | E1: Alternative option (North America) | F1: Final Consolidated CO2 PCF | G1: Use Energy Demand (kWh/yr) | H1: Remarks | I1: Daniel Notes | M1: Profile | N1: Avg PCF | O1: Avg Energy
A2: 1 | B2: HP EliteBook 840 G8 Notebook PC | C2: HP EliteBook 840 G8 | D2: =VLOOKUP(C2,'Full current HP extraction'!A:C,3,FALSE) -> #N/A | E2: =VLOOKUP(C2,'Full current HP extraction'!A:C,2,FALSE) -> #N/A | F2: 200 | G2: 20 | H2: Is the mapping correct?" | I2: Updated Model | M2: 1 | N2: 179 | O2: 16.9
A3: 1 | B3: HP EliteBook 840 14 inch G11 Notebook PC | C3: HP EliteBook 840 14 inch G11 Notebook PC | D3: =VLOOKUP(C3,'Full current HP extraction'!A:C,3,FALSE) -> 171 | E3: =VLOOKUP(C3,'Full current HP extraction'!A:C,2,FALSE) -> 185 | F3: =VLOOKUP(C3,'Current HPE enrichment'!A:C,2,FALSE) -> 171 | G3: =VLOOKUP(C3,'Current HPE enrichment'!A:C,3,FALSE) -> 12.8 | I3: Correct | M3: 2 | N3: 191 | O3: 19.9
A4: 1 | B4: HP EliteBook 840 14 inch G10 Notebook PC | C4: HP EliteBook 840 14 inch G10 Notebook PC | D4: =VLOOKUP(C4,'Full current HP extraction'!A:C,3,FALSE) -> 176 | E4: =VLOOKUP(C4,'Full current HP extraction'!A:C,2,FALSE) -> 192 | F4: =VLOOKUP(C4,'Current HPE enrichment'!A:C,2,FALSE) -> 176 | G4: =VLOOKUP(C4,'Current HPE enrichment'!A:C,3,FALSE) -> 18 | I4: Correct | M4: 3 | N4: 165 | O4: 14.7
A5: 1 | B5: HP EliteBook 840 G8 Notebook PC | C5: HP EliteBook 840 G8 | D5: =VLOOKUP(C5,'Full current HP extraction'!A:C,3,FALSE) -> #N/A | E5: =VLOOKUP(C5,'Full current HP extraction'!A:C,2,FALSE) -> #N/A | F5: 200 | G5: 20 | H5: Same as row 2? | I5: Updated Model | M5: 4 | N5: 265 | O5: 25.3
A6: 1 | B6: HP EliteBook 840 14 inch G11 Notebook PC | C6: HP EliteBook 840 14 inch G11 Notebook PC | D6: =VLOOKUP(C6,'Full current HP extraction'!A:C,3,FALSE) -> 171 | E6: =VLOOKUP(C6,'Full current HP extraction'!A:C,2,FALSE) -> 185 | F6: =VLOOKUP(C6,'Current HPE enrichment'!A:C,2,FALSE) -> 171 | G6: =VLOOKUP(C6,'Current HPE enrichment'!A:C,3,FALSE) -> 12.8 | H6: Sames as row 3? | I6: Same as row 3 | M6: 5 | N6: 122 | O6: 47.2
A7: 1 | B7: HP EliteBook 840 14 inch G9 Notebook PC | C7: HP EliteBook 84014 inch G9 Notebook PC | D7: =VLOOKUP(C7,'Full current HP extraction'!A:C,3,FALSE) -> #N/A | E7: =VLOOKUP(C7,'Full current HP extraction'!A:C,2,FALSE) -> #N/A | F7: 174 | G7: 18 | H7: Is the mapping correct?" | I7: Updated Model | M7: 6 | N7: 183 | O7: 41.5
A8: 1 | B8: HP EliteBook 840 14 inch G10 Notebook PC | C8: HP EliteBook 840 14 inch G10 Notebook PC | D8: =VLOOKUP(C8,'Full current HP extraction'!A:C,3,FALSE) -> 176 | E8: =VLOOKUP(C8,'Full current HP extraction'!A:C,2,FALSE) -> 192 | F8: =VLOOKUP(C8,'Current HPE enrichment'!A:C,2,FALSE) -> 176 | G8: =VLOOKUP(C8,'Current HPE enrichment'!A:C,3,FALSE) -> 18 | H8: Sames as row 4? | I8: Same as row 4 | M8: 7 | N8: 250 | O8: 41
A9: 2 | B9: HP EliteBook 850 G8 Notebook PC | C9: HP EliteBook 850 G8 | D9: =VLOOKUP(C9,'Full current HP extraction'!A:C,3,FALSE) -> Not in source | E9: =VLOOKUP(C9,'Full current HP extraction'!A:C,2,FALSE) -> 220 | F9: 220 | G9: =VLOOKUP(C9,'Current HPE enrichment'!A:C,3,FALSE) -> 26.1 | H9: Is the mapping correct?" | I9: Correct | M9: 8 | N9: 487 | O9: 203
A10: 3 | B10: HP EliteBook 860 16 inch G11 Notebook PC | C10: HP Elitebook 860 G11 | D10: =VLOOKUP(C10,'Full current HP extraction'!A:C,3,FALSE) -> 181 | E10: =VLOOKUP(C10,'Full current HP extraction'!A:C,2,FALSE) -> 198 | F10: =VLOOKUP(C10,'Current HPE enrichment'!A:C,2,FALSE) -> 181 | G10: =VLOOKUP(C10,'Current HPE enrichment'!A:C,3,FALSE) -> 13.4 | H10: Is the mapping correct?" | I10: Correct | M10: 9
A11: 3 | B11: HP EliteBook 860 16 inch G9 Notebook PC | C11: HP EliteBook 860 G9 Notebook PC | D11: =VLOOKUP(C11,'Full current HP extraction'!A:C,3,FALSE) -> 186 | E11: =VLOOKUP(C11,'Full current HP extraction'!A:C,2,FALSE) -> 204 | F11: =VLOOKUP(C11,'Current HPE enrichment'!A:C,2,FALSE) -> 186 | G11: =VLOOKUP(C11,'Current HPE enrichment'!A:C,3,FALSE) -> 15.7 | H11: Is the mapping correct?" | I11: Correct
A12: 1 | B12: HP EliteBook 8 G1i 14 inch Notebook AI PC | C12: HP EliteBook-Zbook 8 G1i 16 inch Notebook AI | D12: =VLOOKUP(C12,'Full current HP extraction'!A:C,3,FALSE) -> 142 | E12: =VLOOKUP(C12,'Full current HP extraction'!A:C,2,FALSE) -> 149 | F12: 167 | G12: 15.6 | H12: Is the mapping correct?" | I12: Correct
A13: 2 | B13: HP EliteBook 8 G1i 16 inch Notebook AI PC | C13: HP EliteBook-Zbook 8 G1i 16 inch Notebook AI | D13: =VLOOKUP(C13,'Full current HP extraction'!A:C,3,FALSE) -> 142 | E13: =VLOOKUP(C13,'Full current HP extraction'!A:C,2,FALSE) -> 149 | F13: =VLOOKUP(C13,'Current HPE enrichment'!A:C,2,FALSE) -> 142 | G13: =VLOOKUP(C13,'Current HPE enrichment'!A:C,3,FALSE) -> 20.9 | H13: Is the mapping correct?"
A14: 2 | B14: HP EliteBook 850 G8 Notebook PC | C14: HP EliteBook 850 G8 | D14: =VLOOKUP(C14,'Full current HP extraction'!A:C,3,FALSE) -> Not in source | E14: =VLOOKUP(C14,'Full current HP extraction'!A:C,2,FALSE) -> 220 | F14: 220 | G14: =VLOOKUP(C14,'Current HPE enrichment'!A:C,3,FALSE) -> 26.1 | H14: Is the mapping correct?" | I14: Correct
A15: 2 | B15: HP EliteBook 860 16 inch G11 Notebook PC | C15: HP Elitebook 860 G11 | D15: =VLOOKUP(C15,'Full current HP extraction'!A:C,3,FALSE) -> 181 | E15: =VLOOKUP(C15,'Full current HP extraction'!A:C,2,FALSE) -> 198 | F15: =VLOOKUP(C15,'Current HPE enrichment'!A:C,2,FALSE) -> 181 | G15: =VLOOKUP(C15,'Current HPE enrichment'!A:C,3,FALSE) -> 13.4 | H15: Same as row 10? | I15: Same as row 10
A16: 2 | B16: HP EliteBook 860 16 inch G9 Notebook PC | C16: HP EliteBook 860 G9 Notebook PC | D16: =VLOOKUP(C16,'Full current HP extraction'!A:C,3,FALSE) -> 186 | E16: =VLOOKUP(C16,'Full current HP extraction'!A:C,2,FALSE) -> 204 | F16: =VLOOKUP(C16,'Current HPE enrichment'!A:C,2,FALSE) -> 186 | G16: =VLOOKUP(C16,'Current HPE enrichment'!A:C,3,FALSE) -> 15.7 | H16: Same as row 11? | I16: Same as row 11
A17: 2 | B17: HP EliteBook 850 G7 Notebook PC | C17: HP EliteBook 850 G7 & HP ZBook Firefly 15 G7 | D17: =VLOOKUP(C17,'Full current HP extraction'!A:C,3,FALSE) -> 195 | E17: =VLOOKUP(C17,'Full current HP extraction'!A:C,2,FALSE) -> 202 | F17: =VLOOKUP(C17,'Current HPE enrichment'!A:C,2,FALSE) -> 195 | G17: =VLOOKUP(C17,'Current HPE enrichment'!A:C,3,FALSE) -> 17 | H17: Is the mapping correct?" | I17: Correct
A18: 3 | B18: HP Elite Dragonfly G2 Notebook PC | C18: HP Elite Dragonfly G2 | D18: =VLOOKUP(C18,'Full current HP extraction'!A:C,3,FALSE) -> 137 | E18: =VLOOKUP(C18,'Full current HP extraction'!A:C,2,FALSE) -> 150 | F18: =VLOOKUP(C18,'Current HPE enrichment'!A:C,2,FALSE) -> 137 | G18: =VLOOKUP(C18,'Current HPE enrichment'!A:C,3,FALSE) -> 12.7 | H18: Is the mapping correct?" | I18: Correct
A19: 3 | B19: HP Elite Dragonfly | C19: HP Elite Dragonfly | D19: =VLOOKUP(C19,'Full current HP extraction'!A:C,3,FALSE) -> 121 | E19: =VLOOKUP(C19,'Full current HP extraction'!A:C,2,FALSE) -> 134 | F19: =VLOOKUP(C19,'Current HPE enrichment'!A:C,2,FALSE) -> 121 | G19: =VLOOKUP(C19,'Current HPE enrichment'!A:C,3,FALSE) -> 13.9 | H19: Is the mapping correct?" | I19: Correct
A20: 3 | B20: HP EliteBook x360 1040 G8 Notebook PC | C20: HP EliteBook x360 830 G8 | D20: =VLOOKUP(C20,'Full current HP extraction'!A:C,3,FALSE) -> Not in source | E20: =VLOOKUP(C20,'Full current HP extraction'!A:C,2,FALSE) -> 200 | F20: 200 | G20: =VLOOKUP(C20,'Current HPE enrichment'!A:C,3,FALSE) -> 17.7 | H20: Is the mapping correct?" | I20: Correct
A21: 4 | B21: HP ZBook Fury 16 G11 Mobile Workstation PC | C21: HP ZBook Fury 16 G11 Mobile Workstation PC | D21: =VLOOKUP(C21,'Full current HP extraction'!A:C,3,FALSE) -> 307 | E21: =VLOOKUP(C21,'Full current HP extraction'!A:C,2,FALSE) -> 315 | F21: =VLOOKUP(C21,'Current HPE enrichment'!A:C,2,FALSE) -> 307 | G21: =VLOOKUP(C21,'Current HPE enrichment'!A:C,3,FALSE) -> 21.3 | I21: Correct
A22: 4 | B22: HP ZBook Fury 15.6 inch G8 Mobile Workstation PC | C22: HP Zbook Fury 15 G8 | D22: =VLOOKUP(C22,'Full current HP extraction'!A:C,3,FALSE) -> Not in source | E22: =VLOOKUP(C22,'Full current HP extraction'!A:C,2,FALSE) -> 300 | F22: 300 | G22: =VLOOKUP(C22,'Current HPE enrichment'!A:C,3,FALSE) -> 38.4 | I22: Correct
A23: 4 | B23: HP ZBook Firefly 16 inch G11 Mobile Workstation PC | C23: HP ZBook Firefly 14 inch G11 A Mobile Workstation PC ENERGY STAR | D23: =VLOOKUP(C23,'Full current HP extraction'!A:C,3,FALSE) -> Not in source | E23: =VLOOKUP(C23,'Full current HP extraction'!A:C,2,FALSE) -> 205 | F23: 205 | G23: 11.73 | H23: Is the mapping correct?" | I23: Correct
A24: 4 | B24: HP ZBook Fury 15 G7 Mobile Workstation | C24: HP ZBook Fury 15 G7 | D24: =VLOOKUP(C24,'Full current HP extraction'!A:C,3,FALSE) -> #N/A | E24: =VLOOKUP(C24,'Full current HP extraction'!A:C,2,FALSE) -> #N/A | F24: 185 | G24: 22 | H24: Is the mapping correct?" | I24: Updated Model
A25: 4 | B25: HP ZBook Firefly 14 inch G8 Mobile Workstation PC | C25: HP ZBook Firefly 14 G8 Mobile Workstation | D25: =VLOOKUP(C25,'Full current HP extraction'!A:C,3,FALSE) -> #N/A | E25: =VLOOKUP(C25,'Full current HP extraction'!A:C,2,FALSE) -> #N/A | F25: 210 | G25: 20.4 | H25: Is the mapping correct?" | I25: Updated Model
A26: 4 | B26: HP ZBook Fury 16 G9 Mobile Workstation PC | C26: HP ZBook Fury 16 G9 Mobile Workstation PC | D26: =VLOOKUP(C26,'Full current HP extraction'!A:C,3,FALSE) -> 319 | E26: =VLOOKUP(C26,'Full current HP extraction'!A:C,2,FALSE) -> 330 | F26: =VLOOKUP(C26,'Current HPE enrichment'!A:C,2,FALSE) -> 319 | G26: =VLOOKUP(C26,'Current HPE enrichment'!A:C,3,FALSE) -> 27.9 | I26: Correct
A27: 4 | B27: HP ZBook Fury 16 G10 Mobile Workstation PC | C27: HP ZBook Fury 16 G10 Mobile Workstation PC | D27: =VLOOKUP(C27,'Full current HP extraction'!A:C,3,FALSE) -> 328 | E27: =VLOOKUP(C27,'Full current HP extraction'!A:C,2,FALSE) -> 342 | F27: =VLOOKUP(C27,'Current HPE enrichment'!A:C,2,FALSE) -> 328 | G27: =VLOOKUP(C27,'Current HPE enrichment'!A:C,3,FALSE) -> 35.5 | I27: Correct
A28: 5 | B28: HP Elite x2 G8 Tablet | C28: HP Elite x2 G8 | D28: =VLOOKUP(C28,'Full current HP extraction'!A:C,3,FALSE) -> 126 | E28: =VLOOKUP(C28,'Full current HP extraction'!A:C,2,FALSE) -> 138 | F28: =VLOOKUP(C28,'Current HPE enrichment'!A:C,2,FALSE) -> 126 | G28: =VLOOKUP(C28,'Current HPE enrichment'!A:C,3,FALSE) -> 11 | H28: Is the mapping correct?" | I28: Correct
A29: 5 | B29: HP Elite x2 G4 | C29: HP Elite x2 G4 | D29: =VLOOKUP(C29,'Full current HP extraction'!A:C,3,FALSE) -> 125 | E29: =VLOOKUP(C29,'Full current HP extraction'!A:C,2,FALSE) -> 137 | F29: =VLOOKUP(C29,'Current HPE enrichment'!A:C,2,FALSE) -> 125 | G29: =VLOOKUP(C29,'Current HPE enrichment'!A:C,3,FALSE) -> 17.9 | I29: Correct
A30: 5 | B30: HP Elite x2 1012 G2 | C30: HP Elite x2 1012 G2 | D30: =VLOOKUP(C30,'Full current HP extraction'!A:C,3,FALSE) -> 116 | E30: =VLOOKUP(C30,'Full current HP extraction'!A:C,2,FALSE) -> 130 | F30: =VLOOKUP(C30,'Current HPE enrichment'!A:C,2,FALSE) -> 116 | G30: =VLOOKUP(C30,'Current HPE enrichment'!A:C,3,FALSE) -> 18.3 | I30: Correct
A31: 6 | B31: HP EliteBook x360 830 G8 Notebook PC | C31: HP EliteBook x360 830 G8 | D31: =VLOOKUP(C31,'Full current HP extraction'!A:C,3,FALSE) -> Not in source | E31: =VLOOKUP(C31,'Full current HP extraction'!A:C,2,FALSE) -> 200 | F31: 200 | G31: =VLOOKUP(C31,'Current HPE enrichment'!A:C,3,FALSE) -> 17.7 | H31: Is the mapping correct?" | I31: Correct
A32: 6 | B32: HP Elite x360 830 13 inch G11 2-in-1 Notebook PC | C32: HP Elite x360 830 13 inch G11 2-in-1 Notebook PC ENERGY STAR | D32: =VLOOKUP(C32,'Full current HP extraction'!A:C,3,FALSE) -> Not in source | E32: =VLOOKUP(C32,'Full current HP extraction'!A:C,2,FALSE) -> 185 | F32: 185 | G32: 11.31 | H32: Is the mapping correct?" | I32: Correct
A33: 6 | B33: HP Elite x360 830 13 inch G10 2-in-1 Notebook PC | C33: HP Elite x360 830 13 inch G10 2-in-1 Notebook PC | D33: =VLOOKUP(C33,'Full current HP extraction'!A:C,3,FALSE) -> 164 | E33: =VLOOKUP(C33,'Full current HP extraction'!A:C,2,FALSE) -> 178 | F33: =VLOOKUP(C33,'Current HPE enrichment'!A:C,2,FALSE) -> 164 | G33: =VLOOKUP(C33,'Current HPE enrichment'!A:C,3,FALSE) -> 12.5 | I33: Correct
A34: 7 | B34: HP Elite Mini 800 G9 Desktop PC | C34: HP Elite Mini 800 G9 Desktop PC | D34: =VLOOKUP(C34,'Full current HP extraction'!A:C,3,FALSE) -> Not in source | E34: =VLOOKUP(C34,'Full current HP extraction'!A:C,2,FALSE) -> 285 | F34: 285 | G34: =VLOOKUP(C34,'Current HPE enrichment'!A:C,3,FALSE) -> 54.03 | I34: Correct
A35: 7 | B35: HP EliteDesk 800 G6 Desktop Mini PC | C35: HP EliteDesk 800 G6 Desktop Mini PC (ENERGY STAR) | D35: =VLOOKUP(C35,'Full current HP extraction'!A:C,3,FALSE) -> Not in source | E35: =VLOOKUP(C35,'Full current HP extraction'!A:C,2,FALSE) -> 250 | F35: 250 | G35: =VLOOKUP(C35,'Current HPE enrichment'!A:C,3,FALSE) -> 40.09 | I35: Correct
A36: 7 | B36: HP EliteDesk 800 G5 Desktop Mini | C36: HP EliteDesk 800 G5 Desktop Mini | D36: =VLOOKUP(C36,'Full current HP extraction'!A:C,3,FALSE) -> 132 | E36: =VLOOKUP(C36,'Full current HP extraction'!A:C,2,FALSE) -> 146 | F36: =VLOOKUP(C36,'Current HPE enrichment'!A:C,2,FALSE) -> 132 | G36: =VLOOKUP(C36,'Current HPE enrichment'!A:C,3,FALSE) -> 28.7 | I36: Correct
A37: 7 | B37: HP EliteDesk 800 G6 Tower PC | C37: HP EliteDesk 800 G6 Desktop Mini PC (ENERGY STAR) | D37: =VLOOKUP(C37,'Full current HP extraction'!A:C,3,FALSE) -> Not in source | E37: =VLOOKUP(C37,'Full current HP extraction'!A:C,2,FALSE) -> 250 | F37: 250 | G37: =VLOOKUP(C37,'Current HPE enrichment'!A:C,3,FALSE) -> 40.09 | I37: Correct
A38: 7 | B38: HP Elite Tower 800 G9 Desktop PC | C38: HP Elite Tower 800 G9 Desktop PC | D38: =VLOOKUP(C38,'Full current HP extraction'!A:C,3,FALSE) -> 212 | E38: =VLOOKUP(C38,'Full current HP extraction'!A:C,2,FALSE) -> 235 | F38: =VLOOKUP(C38,'Current HPE enrichment'!A:C,2,FALSE) -> 212 | G38: =VLOOKUP(C38,'Current HPE enrichment'!A:C,3,FALSE) -> 48.8 | I38: Correct
A39: 7 | B39: HP Engage One Pro AIO System | C39: HP Engage One Pro AiO System (15.6) | D39: =VLOOKUP(C39,'Full current HP extraction'!A:C,3,FALSE) -> 206 | E39: =VLOOKUP(C39,'Full current HP extraction'!A:C,2,FALSE) -> 218 | F39: =VLOOKUP(C39,'Current HPE enrichment'!A:C,2,FALSE) -> 206 | G39: =VLOOKUP(C39,'Current HPE enrichment'!A:C,3,FALSE) -> 24.8 | H39: Is the mapping correct?" | I39: Correct
A40: 7 | B40: HP EliteDesk 800 G4 DM 65W | C40: HP EliteDesk 800 G4 DM | D40: =VLOOKUP(C40,'Full current HP extraction'!A:C,3,FALSE) -> 126 | E40: =VLOOKUP(C40,'Full current HP extraction'!A:C,2,FALSE) -> 139 | F40: =VLOOKUP(C40,'Current HPE enrichment'!A:C,2,FALSE) -> 126 | G40: =VLOOKUP(C40,'Current HPE enrichment'!A:C,3,FALSE) -> 26.1 | H40: Is the mapping correct?" | I40: Correct
...

Sheet New HP Devices
A1: Profile | B1: Model | C1: PCF (Kg CO2) | D1: Use Energy Demand (kWh/yr) | H1: Profile | I1: Avg PCF | J1: Avg Energy
A2: 1 | B2: EliteBook 6 G1i 14 AI | C2: 174 | D2: 19.1 | H2: 1 | I2: =(C2+C3)/2 -> 159 | J2: =(D2+D3)/2 -> 18.2
A3: 1 | B3: EliteBook 6 G1a 14 AI | C3: 144 | D3: 17.3 | H3: 2 | I3: =(C4+C5)/2 -> 156.5 | J3: =(D4+D5)/2 -> 18.7
A4: 2 | B4: EliteBook 6 G1i 16 AI | C4: 169 | D4: 20.1 | H4: 3 | I4: =(C6+C7)/2 -> 184 | J4: =(D6+D7)/2 -> 20.55
A5: 2 | B5: EliteBook 6 G1a 16 AI | C5: 144 | D5: 17.3 | H5: 4 | I5: =(C10+C11)/2 -> 245.5 | J5: =(D10+D11)/2 -> 22.55
A6: 3 | B6: EliteBook X G1a NGAI | C6: 183 | D6: 26.9 | H6: 5 | I6: =C9 -> 188 | J6: =D9 -> 14.6
A7: 3 | B7: EliteBook X G1i NGAI | C7: 185 | D7: 14.2 | H7: 6 | I7: =C8 -> 102 | J7: =D8 -> 11
A8: 6 | B8: EliteBook 8 G1i Flip AI | C8: 102 | D8: 11 | H8: 7 | I8: =(C12+C13+C14)/3 -> 163.33333 | J8: =(D12+D13+D14)/3 -> 55.133333
A9: 5 | B9: EliteBook X Flip NGAI | C9: 188 | D9: 14.6 | H9: 8 | I9: =C16 -> 693 | J9: =D16 -> 309.3
A10: 4 | B10: ZBook Fury G1i 16 | C10: 252 | D10: 28.2 | E10: Estimated | H10: 9 | I10: =C17 -> 150 | J10: =D17 -> 14.5
A11: 4 | B11: ZBook Power 16 G11 A | C11: 239 | D11: 16.9
A12: 7 | B12: ProDesk 4 Mini G1i | C12: 163 | D12: 50.6
A13: 7 | B13: EliteDesk 8 G1a Mini | C13: 175 | D13: 50.6
A14: 7 | B14: ProDesk 4 G1i SFF | C14: 152 | D14: 64.2
A15: 7 | B15: EliteDesk 805 G9 SFF | C15: 305 | D15: 35.4
A16: 8 | B16: Z4 G5 | C16: 693 | D16: 309.3
A17: 9 | B17: Engage Go 10 | C17: 150 | D17: 14.5 | E17: No clear profile match

Sheet New Lenovo Devices
A1: Device | B1: Persona | C1: Profile | D1: Lenovo Models | E1: PCF | F1: Energy per year KwH | G1: Remarks | I1: Profile | J1: Avg PCF | K1: Avg Energy
A2: Laptop | B2: Profile 1 – Standard User | C2: 1 | D2: Option 1 - ThinkPad T14 Gen 6, Core Ultra 5 235U, 16GB, 256GB, Touch | E2: 175 | F2: 11.7 | I2: 1 | J2: =(E2+E3)/2 -> 178.5 | K2: =(F2+F3)/2 -> 14.54
C3: 1 | D3: Option 2 - ThinkPad T14 Gen 5, AMD Ryzen 5 PRO 8540U, 16GB, 256GB, Touch | E3: 182 | F3: 17.38 | I3: 2 | J3: =(E4+E5)/2 -> 192.5 | K3: =(F4+F5)/2 -> 14.46
A4: Laptop | B4: Profile 2 – Std User w/ customization | C4: 2 | D4: Option 1 - ThinkPad T16 Gen 4, Intel Core Ultra 7 265U, 16GB, 256GB, Touch | E4: 193 | F4: 14.62 | I4: 3 | J4: =(E6+E7)/2 -> 176.5 | K4: =(F6+F7)/2 -> 14.345
C5: 2 | D5: Option 2 - ThinkPad T16 Gen 4, AMD Ryzen AI 7 PRO 350, 16GB, 256GB, Touch | E5: 192 | F5: 14.3 | I5: 4 | J5: =E8 -> 260.5 | K5: =F8 -> 21.75
A6: Laptop | B6: Profile 3 – VIP Users | C6: 3 | D6: Option 1 - ThinkPad X1 Carbon G13, Intel Core Ultra 7 265U, 16GB, 256GB, Touch | E6: 177 | F6: 17.48 | G6: Only G12 avaiable | I6: 5 | J6: =E9 -> 79 | K6: =F9 -> 15.4
C7: 3 | D7: Option 2 - ThinkPad X9-14 Gen 1, Intel Core Ultra 7 268V, 32GB, 256GB, Touch | E7: 176 | F7: 11.21 | I7: 6 | J7: =E10 -> 241 | K7: =F10 -> 15.65
A8: Laptop | B8: Profile 4 – Max Performance | C8: 4 | D8: MWST ThinkPad P16v Gen 2, Intel Core Ultra 7 165H vPRO, 32GB, 1TB, RTX 2000 | E8: =(239+282)/2 -> 260.5 | F8: =(16.91+26.59)/2 -> 21.75 | G8: Mean between Gen 3 and gen 1 | I8: 7 | J8: =(E11+E12)/2 -> 382 | K8: =(F11+F12)/2 -> 47.995
A9: Laptop | B9: Profile 5 – 2-in-1 Detachable | C9: 5 | D9: ThinkPad X12 Detachable Gen 2, Intel Core Ultra 5 134U, 16GB, 256GB | E9: 79 | F9: 15.4 | G9: with keyboard | I9: 8 | J9: =E14 -> 2205 | K9: =F14 -> 580.88
A10: Laptop | B10: Profile 6 – 2-in-1 Convertible | C10: 6 | D10: ThinkPad T14s 2-in-1 Gen 1, Intel Core Ultra 5 235U, 16GB, 256GB, Touch | E10: 241 | F10: 15.65 | G10: Used gen 3 for kwh. Could be more | I10: 9 | J10: =E15 -> 79 | K10: =F15 -> 15.4
A11: Desktop | B11: Profile 7 – Standard Desktop | C11: 7 | D11: Tiny - ThinkCentre M75q Gen 5, AMD Ryzen 5 PRO 8500GE, 16GB, 256GB | E11: 285 | F11: 33.8
C12: 7 | D12: SFF - ThinkCentre M75s Gen5, AMD Ryzen 5 8500G, 16GB, 256GB | E12: 479 | F12: 62.19
C13: 7 | D13: Tower - ThinkCentre M70t Gen 6, Intel Core Ultra 7 265, 16GB, 256GB | E13: 503 | F13: 90.18
A14: Desktop | B14: Profile 8 – Workstation CAD | C14: 8 | D14: ThinkStation P5, Intel® Xeon® W3-2525 Processor, 32GB, 1TB, RTX 4000 | E14: 2205 | F14: 580.88
A15: Tablet | B15: Profile 9 – Standard User Tablet | C15: 9 | D15: ThinkPad X12 Detachable Gen 2, Intel Core Ultra 5 134U, 16GB, 256GB | E15: 79 | F15: 15.4 | G15: with keyboard

Sheet New Dell devices
A1: Profile | B1: Model | C1: Total Carbon Footprint (EU Baseline) KgCO2 | D1: Energy Demand (Yearly TEC) kWh/a | J1: Profile | K1: Avg PCF | L1: Avg Energy
A2: 2 | B2: Dell Pro 16 Clamshell - PC16250 | C2: 118 | D2: 21.5 | J2: 1 | K2: =C3 -> 107 | L2: =D3 -> 20
A3: 1 | B3: Dell Pro Clamshell 14 - PC14250 | C3: 107 | D3: 20 | J3: 2 | K3: =C2 -> 118 | L3: =D2 -> 21.5
A4: 3 | B4: Dell Pro 14 Clamshell - PA14250 | C4: 104 | D4: 17.7 | J4: 3 | K4: =C4 -> 104 | L4: =D4 -> 17.7
A5: 4 | B5: Dell Pro Max 16 (MC16250) | C5: 118 | D5: 19.3 | J5: 4 | K5: =C5 -> 118 | L5: =D5 -> 19.3
A6: 6 | B6: Dell Pro 14 - 2 in 1 PB14250 | C6: 107 | D6: 18.5 | J6: 5 | K6: =C10 -> 110 | L6: =D10 -> 17.8
A7: 7 | B7: Dell Pro Micro - QCM1250 | C7: 77.6 | D7: 25.3 | J7: 6 | K7: =C6 -> 107 | L7: =D6 -> 18.5
A8: 7 | B8: Dell Pro Slim - QCS1250 | C8: 163 | D8: 44.4 | J8: 7 | K8: =(C7+C8)/2 -> 120.3 | L8: =(D7+D8)/2 -> 34.85
A9: 8 | B9: Dell Pro Max T2 (FCT2250) | C9: 406 | D9: 175 | J9: 8 | K9: =C9 -> 406 | L9: =D9 -> 175
A10: 5 | B10: Latitude 7350 Detachable | C10: 110 | D10: 17.8 | J10: 9 | K10: =(C11+C12)/2 -> 124 | L10: =(D11+D12)/2 -> 21.2
A11: 9 | B11: Latitude 7030 Rugged | C11: 115 | D11: 21.2
A12: 9 | B12: Latitude 7230 Rugged | C12: 133 | D12: 21.2

Sheet Profile devices mapping
A3: CapEx | C3: HP | H3: Lenovo | M3: Dell
A4: Profile | B4: Type of Profile | C4: OEM Model | D4: Processor Brand | E4: Processor Model | F4: Average Cost (12GB) | G4: Average Cost (32GB) | H4: OEM Model | I4: Processor Brand | J4: Processor Model | K4: Average Cost (12GB) | L4: Average Cost (32GB) | M4: OEM Model | N4: Processor Brand | O4: Processor Model | P4: Average Cost (12GB) | Q4: Average Cost (32GB)
A5: Profile 1 | B5: Laptop - Standard user | C5: EliteBook 6 G1i 14 | D5: Intel | E5: Ultra 5 - 235U | F5: $566 | G5: $683 | H5: T14 Gen 6 | I5: Intel | J5: Ultra 5 - 235U | K5: $681 | L5: $857 | M5: Dell Pro 14 | N5: Intel | O5: Ultra 5 - 235U | P5: $1,011 | Q5: -
A6: Profile 1 | B6: Laptop - Standard user | C6: EliteBook 6 G1a 14 | D6: AMD | E6: Ryzen 5 PRO 230 | F6: $535 | G6: $652 | H6: ThinkPad L14 Gen 6 | I6: AMD | J6: Ryzen 5 PRO 230 | K6: $591 | L6: $767 | M6: Dell Pro 14 | N6: AMD | O6: Ryzen 5 PRO 230 | P6: $973 | Q6: -
A7: Profile 2 | B7: Laptop - Standard user with customization | C7: EliteBook 6 G1i 16 | D7: Intel | E7: U5-235U | F7: $586 | G7: $704 | H7: T16 Gen 4 | I7: Intel | J7: Ultra 5 235U | K7: $736 | L7: $912 | M7: Dell Pro 16 | N7: Intel | O7: Ultra 5 - 235U | P7: $995 | Q7: -
A8: Profile 2 | B8: Laptop - Standard user with customization | C8: EliteBook 6 G1a 16 | D8: AMD | E8: Ryzen 5 PRO 230 | F8: $556 | G8: $672 | H8: ThinkPad L16 Gen 2 | I8: AMD | J8: Ryzen 5 PRO 230 | K8: $714 | L8: $890 | M8: Dell Pro 16 | N8: AMD | O8: Ryzen AI 7 350 | P8: $977 | Q8: -
A9: Profile 3 | B9: Laptop - User with great performance needs | C9: EliteBook X G1i NGAI | D9: Intel | E9: U7-266V | F9: $890 | G9: $961 | H9: X1 Carbon Gen 13 | I9: Intel | J9: Ultra 7 - 265U | K9: $1,117 | L9: - | M9: Dell Pro 14 Premium | N9: Intel | O9: Ultra 7 266V | P9: $1,591 | Q9: -
A10: Profile 3 | B10: Laptop - User with great performance needs | C10: EliteBook X G1a NGAI | D10: AMD | E10: Ryzen AI 7 Pro 360 | F10: $901 | G10: $1,043 | H10: X9-14 Gen 1 | I10: Intel | J10: Ultra 7 - 268V | K10: - | L10: $1,219 | M10: - | N10: - | O10: - | P10: - | Q10: -
A11: Profile 4 | B11: Laptop - User with max performance needs | C11: ZBook Fury G1i 16 | D11: Intel | E11: U7-265HX | F11: - | G11: $1,560 | H11: P16v Gen 3 | I11: Intel | J11: Ultra 7 - 265H | K11: - | L11: $2,210 | M11: Dell Pro Max 16 | N11: Intel | O11: Ultra 7 265H | P11: - | Q11: $1,748
A12: Profile 4 | B12: Laptop - User with max performance needs | C12: Zbook Power 16 G11a | D12: AMD | E12: Ryzen 9 Pro 8945HS | F12: - | G12: $1,131 | H12: - | I12: AMD | J12: - | K12: - | L12: - | M12: - | N12: - | O12: - | P12: - | Q12: -
A13: Profile 5 | B13: Laptop - 2-in-1 User (tablet) | C13: - | D13: - | E13: - | F13: - | G13: - | H13: X12 Detachable Gen 2 | I13: Intel | J13: Ultra 5 - 134U | K13: - | L13: $1,232 | M13: Dell Latitude 7350 Detachable | N13: Intel | O13: Ultra 7 164U | P13: - | Q13: $1,901
A14: Profile 6 | B14: Laptop - 2-in-1 User (convertible) | C14: EliteBook X Flip G1i NGAI | D14: Intel | E14: U5- 236V | F14: $790 | G14: - | H14: T14s 2-in-1 Gen 1 | I14: Intel | J14: Ultra 5 - 235U | K14: $999 | L14: - | M14: Dell Pro 14 Plus | N14: Intel | O14: Ultra 5 235U | P14: $1,267 | Q14: -
A15: Profile 6 | B15: Laptop - 2-in-1 User (convertible) | C15: EliteBook 8 G1i Flip | D15: Intel | E15: U5-235U | F15: $804 | G15: - | H15: - | I15: - | J15: - | K15: - | L15: - | M15: - | N15: - | O15: - | P15: - | Q15: -
... A20: Profile 8 | B20: Desktop - Workstation CAD | C20: Workstation Z4 G5 | D20: Intel | E20: Xeon W3-2525 | F20: NA | G20: $1,795 | H20: P5 | I20: Intel | J20: Xeon W3 - 2525 | K20: - | L20: $4,174 | M20: Dell Pro Max Tower T2 | N20: Intel | O20: Ultra 9 285 | P20: - | Q20: $1,749
A21: Profile 9 | B21: Tablet - Standard | C21: - | D21: - | E21: - | H21: X12 Detachable Gen 2 | I21: Intel | J21: Ultra 5 - 134U | K21: $1,011 | L21: - | M21: Dell Latitude 7030 | N21: Intel | O21: i5-1240U | P21: $1,895 | Q21: -
A26: Notes
A27: Dell removed Dell Pro Micro QBM1250 & Dell Pro Slim
A28: Dell did not provide the information for 32 GB
A29: Hilighted in red specs not updated based on our request
A30: HP did not provide the requested memory SKUs
A32: HP is offering U7-265HX processor for Profile 4 (Intel) instead of Ultra 7 165H vPRO, RTX 2000 ADA, AX211, PL. Clarify with them if the processor proposed also includes RTX 2000 ADA graphics | H32: Not in portofolio from HP - Yes confirmed
A33: Dell in Profile 2 (AMD) is offering AMD Ryzen(TM) AI 7 350 Processor with AMD Radeon(TM) 860M graphics instead of AMD Ryzen™ 5 PRO 230 required. Needs clarification
A34: Dell in Profile 4 (Intel)( is offering Intel Core Ultra 7 265H, vPro Enterprise (24MB, 16 cores, 16 threads, up to 5.30 GHz Turbo, 45W) instead of Ultra 7 165H vPRO, RTX 2000 ADA, AX211, PL required. Needs clarification
A35: Dell in Profile 8 (Intel) is offering Intel Core Ultra 9 285 processor instead of Intel® Xeon® W3-2525 Processor (3.50 GHz up to 4.50 GHz). Needs clarification
A36: Lenovo offered in Profile 4 "Ultra 7 265H vPRO, 32GB, 1TB, RTX 2000" instead of "Ultra 7 165H vPRO, RTX 2000 ADA, AX211, PL". Clarify with them
A37: Lenovo offered in Profile 6 "Intel Ultra 5 235U" instead of "Intel Ultra 5 236V". Needs clarification
A38: Lenovo offered In profile 7 Ryzen 7 PRO 8700G instead of AMD Ryzen 5 8500G. Needs clarification

Sheet Current HPE enrichment
A1: Model | B1: Total PCF for Europe (kg CO2e) | C1: Use Energy Demand (kWh/yr)
A2: HP EliteBook 840 G8 - ZBook Firefly 14 G8 | B2: 176 | C2: 17
A3: HP EliteBook 840 14 inch G11 Notebook PC | B3: 171 | C3: 12.8
A4: HP EliteBook 840 14 inch G10 Notebook PC | B4: 176 | C4: 18
A5: HP EliteBook 840 G9 | B5: 200 (North America), | C5: 21.2
A6: HP EliteBook 850 G8 | B6: 220 (North America), | C6: 26.1
A7: HP Elitebook 860 G11 | B7: 181 | C7: 13.4
A8: HP EliteBook 860 G9 Notebook PC | B8: 186 | C8: 15.7
A9: HP EliteBook-Zbook 8 G1i 16 inch Notebook AI | B9: 142 | C9: 20.9
A10: HP EliteBook 850 G7 & HP ZBook Firefly 15 G7 | B10: 195 | C10: 17
A11: HP Elite Dragonfly G2 | B11: 137 | C11: 12.7
A12: HP Elite Dragonfly | B12: 121 | C12: 13.9
A13: HP EliteBook x360 830 G8 | B13: 200 (North America), | C13: 17.7
A14: HP ZBook Fury 16 G11 Mobile Workstation PC | B14: 307 | C14: 21.3
A15: HP ZBook Fury 15 G8 | B15: 300 (North America), | C15: 38.4
A16: HP ZBook Firefly 14 inch G11 A Mobile Workstation PC | B16: 205 (North America), | C16: 11.73
A17: HP ZBook Fury 16 G9 Mobile Workstation PC | B17: 319 | C17: 27.9
A18: HP ZBook Fury 16 G10 Mobile Workstation PC | B18: 328 | C18: 35.5
A19: HP Elite x2 G8 | B19: 126 | C19: 11
A20: HP Elite x2 G4 | B20: 125 | C20: 17.9
A21: HP Elite x2 1012 G2 | B21: 116 | C21: 18.3
A22: HP Elite x360 830 13 inch G11 2-in-1 Notebook PC | B22: 185 (North America), | C22: 11.31
A23: HP Elite x360 830 13 inch G10 2-in-1 Notebook PC | B23: 164 | C23: 12.5
A24: HP Elite Mini 800 G9 Desktop PC | B24: 285 (North America), | C24: 54.03
A25: HP EliteDesk 800 G6 Desktop Mini PC (ENERGY STAR) | B25: 250 (North America), | C25: 40.09
A26: HP EliteDesk 800 G5 Desktop Mini | B26: 132 | C26: 28.7
A27: HP Elite Tower 800 G9 Desktop PC | B27: 212 | C27: 48.8
A28: HP Engage One Pro AiO System (15.6) | B28: 206 | C28: 24.8
A29: HP EliteDesk 800 G4 DM | B29: 126 | C29: 26.1
A30: HP Z4 G4 Tower | B30: 712 | C30: 356.1
A31: HP Z4 G5 Workstation | B31: 693 | C31: 309.3
A32: HP Z2 Tower G9 Workstation Desktop PC | B32: 400 | C32: 135.3
A33: HP Engage Go 13.5 inch Mobile System | B33: 142 | C33: 14.7

Sheet Full current HP extraction
A1: Name and model | B1: Total PCF (North America) | C1: Total PCF (Europe) | D1: Total PCF (Asia Pacific) | E1: Manufacturing (%) | F1: Use (%) | G1: Distribution (%) | H1: End of Life (%) | I1: Main board and other boards (%) | J1: Solid state drive (SSD) (%) | K1: Display (%) | L1: Chassis (%) | M1: Batteries (%) | N1: Power supply unit & external cables (%) | O1: Others (%) | P1: Packaging (%) | Q1: Source
A2: HP Z4 G4 Tower | B2: 880 | C2: 712 | D2: 1302 | E2: 0.28 | F2: 0.71 | G2: < 1% | H2: < 1% | I2: 0.39 | J2: 0.23 | K2: Not in source | L2: 0.22 | M2: < 1% | N2: 0.11 | O2: 0.04 | P2: < 1% | Q2: 1
A3: HP Z4 G5 Workstation | B3: 839 | C3: 693 | D3: 1205 | E3: 0.35 | F3: 0.65 | G3: < 1% | H3: < 1% | I3: 0.49 | J3: 0.2 | K3: Not in source | L3: 0.16 | M3: < 1% | N3: 0.09 | O3: 0.04 | P3: 0.02 | Q3: 2
A4: HP Z2 Tower G9 Workstation Desktop PC | B4: 464 | C4: 400 | D4: 624 | E4: 0.48 | F4: 0.51 | G4: < 1% | H4: < 1% | I4: 0.42 | J4: 0.26 | K4: Not in source | L4: 0.13 | M4: Not in source | N4: 0.12 | O4: 0.05 | P4: 0.02 | Q4: 3
A5: HP ZBook Fury 16 G10 Mobile Workstation PC | B5: 342 | C5: 328 | D5: 375 | E5: 0.85 | F5: 0.15 | G5: < 1% | H5: < 1% | I5: 0.51 | J5: 0.2 | K5: 0.13 | L5: 0.09 | M5: 0.03 | N5: 0.03 | O5: 0.02 | P5: < 1% | Q5: 4
A6: HP ZBook Fury 16 G9 Mobile Workstation PC | B6: 330 | C6: 319 | D6: 356 | E6: 0.88 | F6: 0.12 | G6: < 1% | H6: < 1% | I6: 0.51 | J6: 0.2 | K6: 0.13 | L6: 0.09 | M6: 0.03 | N6: 0.03 | O6: 0.01 | P6: < 1% | Q6: 5
A7: HP ZBook Fury 16 G11 Mobile Workstation PC | B7: 315 | C7: 307 | D7: 335 | E7: 0.9 | F7: 0.09 | G7: < 1% | H7: < 1% | I7: 0.52 | J7: 0.2 | K7: 0.13 | L7: 0.08 | M7: 0.03 | N7: 0.03 | O7: < 1% | P7: < 1% | Q7: 6
A8: HP Zbook Fury 15 G8 | B8: 300 | C8: Not in source | D8: Not in source | E8: 0.71 | F8: 0.23 | G8: 0.06 | H8: 0 | I8: 0.41 | J8: 0.26 | K8: 0.15 | L8: 0.06 | M8: 0.05 | N8: 0.04 | O8: 0.02 | P8: < 1% | Q8: 7
A9: HP Elite Tower 800 G9 Desktop PC | B9: 235 | C9: 212 | D9: 292 | E9: 0.63 | F9: 0.36 | G9: < 1% | H9: < 1% | I9: 0.52 | J9: 0.2 | K9: Not in source | L9: 0.17 | M9: Not in source | N9: 0.03 | O9: 0.07 | P9: 0.02 | Q9: 8
A10: HP Elite Mini 800 G9 Desktop PC | B10: 285 | C10: Not in source | D10: Not in source | E10: 0.49 | F10: 0.51 | G10: 0 | H10: 0 | I10: 43.2% | J10: 41.0% | K10: Not in source | L10: 3.6% | M10: Not in source | N10: 5.5% | O10: 3.6% | P10: 0.4% | Q10: 9
A11: HP EliteDesk 800 G6 Desktop Mini PC (ENERGY STAR) | B11: 250 | C11: Not in source | D11: Not in source | E11: 0.56 | F11: 0.43 | G11: 0 | H11: 0.01 | I11: 0.63 | J11: 0.21 | K11: Not in source | L11: 0.03 | M11: Not in source | N11: 0.04 | O11: 0.04 | P11: Not in source | Q11: 10
A12: HP Engage One Pro AiO System (15.6) | B12: 218 | C12: 206 | D12: 246 | E12: 0.78 | F12: 0.2 | G12: < 1% | H12: < 1% | I12: 0.37 | J12: 0.17 | K12: 0.21 | L12: 0.13 | M12: < 1% | N12: 0.07 | O12: 0.02 | P12: 0.02 | Q12: 11
A13: HP EliteBook 850 G8 | B13: 220 | C13: Not in source | D13: Not in source | E13: 0.73 | F13: 0.21 | G13: 0.06 | H13: 0 | I13: 0.48 | J13: 0.18 | K13: 0.2 | L13: 0.07 | M13: 0.03 | N13: 0.02 | O13: 0.02 | P13: 0.01 | Q13: 12
A14: HP EliteBook 860 G9 Notebook PC | B14: 204 | C14: 186 | D14: 202 | E14: 0.8 | F14: 0.11 | G14: 0.09 | H14: < 1% | I14: 0.42 | J14: 0.18 | K14: 0.23 | L14: 0.1 | M14: 0.04 | N14: 0.02 | O14: 0.01 | P14: < 1% | Q14: 13
A15: HP EliteBook 850 G7 & HP ZBook Firefly 15 G7 | B15: 202 | C15: 195 | D15: 217 | E15: 0.88 | F15: 0.12 | G15: < 1% | H15: < 1% | I15: 0.32 | J15: 0.33 | K15: 0.2 | L15: 0.08 | M15: 0.02 | N15: 0.02 | O15: 0.01 | P15: < 1% | Q15: 14
A16: HP ZBook Firefly 14 inch G11 A Mobile Workstation PC ENERGY STAR | B16: 205 | C16: Not in source | D16: Not in source | E16: 0.83 | F16: 0.12 | G16: 0.05 | H16: 0 | I16: 0.34 | J16: 0.34 | K16: 0.17 | L16: 0.08 | M16: 0.03 | N16: 0.02 | O16: 0.02 | P16: Not in source | Q16: 15
A17: HP EliteBook 840 G9 | B17: 200 | C17: Not in source | D17: Not in source | E17: 0.76 | F17: 0.19 | G17: 0.05 | H17: 0 | I17: 0.46 | J17: 0.19 | K17: 0.19 | L17: 0.08 | M17: 0.04 | N17: 0.03 | O17: 0.02 | P17: < 1% | Q17: 16
A18: HP EliteBook x360 830 G8 | B18: 200 | C18: Not in source | D18: Not in source | E18: 0.78 | F18: 0.16 | G18: 0.06 | H18: 0 | I18: 0.48 | J18: 0.19 | K18: 0.18 | L18: 0.08 | M18: 0.03 | N18: 0.03 | O18: 0.02 | P18: < 1% | Q18: 17
A19: HP Elitebook 860 G11 | B19: 198 | C19: 181 | D19: 194 | E19: 0.81 | F19: 0.09 | G19: 0.09 | H19: < 1% | I19: 0.42 | J19: 0.18 | K19: 0.23 | L19: 0.03 | M19: 0.1 | N19: 0.02 | O19: 0.01 | P19: < 1% | Q19: 18
A20: HP EliteBook 840 14 inch G10 Notebook PC | B20: 192 | C20: 176 | D20: 196 | E20: 0.79 | F20: 0.13 | G20: 0.08 | H20: < 1% | I20: 0.44 | J20: 0.19 | K20: 0.21 | L20: 0.09 | M20: 0.03 | N20: 0.02 | O20: 0.02 | P20: < 1% | Q20: 19
A21: HP EliteBook 840 14 inch G11 Notebook PC | B21: 185 | C21: 171 | D21: 184 | E21: 0.82 | F21: 0.1 | G21: 0.08 | H21: < 1% | I21: 0.44 | J21: 0.19 | K21: 0.21 | L21: 0.09 | M21: 0.03 | N21: 0.02 | O21: 0.02 | P21: < 1% | Q21: 20
A22: HP Elite x360 830 13 inch G11 2-in-1 Notebook PC ENERGY STAR | B22: 185 | C22: Not in source | D22: Not in source | E22: 0.81 | F22: 0.13 | G22: 0.06 | H22: 0 | I22: 0.46 | J22: 0.19 | K22: 0.19 | L22: 0.08 | M22: 0.03 | N22: 0.03 | O22: 0.02 | P22: Not in source | Q22: 21
A23: HP EliteBook 840 G8 - ZBook Firefly 14 G8 | B23: 182 | C23: 176 | D23: 198 | E23: 0.86 | F23: 0.13 | G23: < 1% | H23: < 1% | I23: 0.29 | J23: 0.37 | K23: 0.2 | L23: 0.06 | M23: 0.03 | N23: 0.02 | O23: 0.01 | P23: < 1% | Q23: 22
A24: HP Elite x360 830 13 inch G10 2-in-1 Notebook PC | B24: 178 | C24: 164 | D24: 177 | E24: 0.82 | F24: 0.1 | G24: 0.08 | H24: < 1% | I24: 0.44 | J24: 0.2 | K24: 0.21 | L24: 0.08 | M24: 0.03 | N24: 0.02 | O24: 0.02 | P24: < 1% | Q24: 23
A25: HP Engage Go 13.5 inch Mobile System | B25: 166 | C25: 142 | D25: 154 | E25: 0.71 | F25: 0.12 | G25: 0.16 | H25: < 1% | I25: 0.3 | J25: 0.25 | K25: 0.26 | L25: 0.08 | M25: 0.03 | N25: 0.03 | O25: 0.03 | P25: 0.03 | Q25: 24
A26: HP Elite Dragonfly G2 | B26: 150 | C26: 137 | D26: 150 | E26: 0.79 | F26: 0.12 | G26: 0.08 | H26: < 1% | I26: 0.27 | J26: 0.24 | K26: 0.3 | L26: 0.09 | M26: 0.04 | N26: 0.03 | O26: 0.02 | P26: < 1% | Q26: 25
A27: HP EliteBook-Zbook 8 G1i 16 inch Notebook AI | B27: 149 | C27: 142 | D27: 166 | E27: 0.82 | F27: 0.17 | G27: < 1% | H27: < 1% | I27: 0.58 | J27: 0.23 | K27: 0.3 | L27: 0.04 | M27: 0.1 | N27: 0.03 | O27: Not in source | P27: < 1% | Q27: 26
A28: HP EliteDesk 800 G5 Desktop Mini | B28: 146 | C28: 132 | D28: 180 | E28: 0.64 | F28: 0.35 | G28: < 1% | H28: < 1% | I28: 0.51 | J28: 0.31 | K28: Not in source | L28: 0.05 | M28: < 1% | N28: 0.03 | O28: 0.1 | P28: < 1% | Q28: 27
A29: HP EliteDesk 800 G4 DM | B29: 139 | C29: 126 | D29: 169 | E29: 0.66 | F29: 0.33 | G29: < 1% | H29: < 1% | I29: 0.46 | J29: 0.32 | K29: Not in source | L29: 0.08 | M29: < 1% | N29: 0.04 | O29: 0.1 | P29: < 1% | Q29: 28
A30: HP Elite x2 G8 | B30: 138 | C30: 126 | D30: 138 | E30: 0.8 | F30: 0.11 | G30: 0.08 | H30: < 1% | I30: 0.33 | J30: 0.26 | K30: 0.27 | L30: 0.05 | M30: 0.04 | N30: 0.03 | O30: 0.02 | P30: < 1% | Q30: 29
A31: HP Elite x2 G4 | B31: 137 | C31: 125 | D31: 146 | E31: 0.74 | F31: 0.18 | G31: 0.06 | H31: < 1% | I31: 0.27 | J31: 0.28 | K31: 0.29 | L31: 0.05 | M31: 0.04 | N31: 0.03 | O31: 0.02 | P31: < 1% | Q31: 30
A32: HP Elite Dragonfly | B32: 134 | C32: 121 | D32: 137 | E32: 0.76 | F32: 0.15 | G32: 0.08 | H32: < 1% | I32: 0.21 | J32: 0.28 | K32: 0.3 | L32: 0.1 | M32: 0.05 | N32: 0.04 | O32: 0.02 | P32: < 1% | Q32: 31
A33: HP Elite x2 1012 G2 | B33: 130 | C33: 116 | D33: 138 | E33: 0.73 | F33: 0.2 | G33: 0.07 | H33: < 1% | I33: 0.24 | J33: 0.31 | K33: 0.3 | L33: 0.04 | M33: 0.04 | N33: 0.04 | O33: 0.02 | P33: < 1% | Q33: 32

Sheet profile old
B3: Count of Netbios_Name0 | C3: Budget Replacement Year
A4: ModelName | B4: Persona Profile | C4: 2018 | D4: 2019 | E4: 2020 | F4: 2021 | G4: 2022 | H4: 2023 | I4: 2024 | J4: 2025 | K4: 2026 | L4: 2027 | M4: 2028 | N4: 2029 | O4: 2030 | P4: NULL | Q4: Grand Total
B5: New Installations, Isolated Clients, Inventory Issue | P5: 5 | Q5: 5
A6: 10MLS04C00 | B6: New Installations, Isolated Clients, Inventory Issue | P6: 1 | Q6: 1
A7: 21CGS0FR00 | B7: New Installations, Isolated Clients, Inventory Issue | P7: 1 | Q7: 1
A8: 21SDS0BB00 | B8: New Installations, Isolated Clients, Inventory Issue | P8: 1 | Q8: 1
A9: 21SDS0BB03 | B9: New Installations, Isolated Clients, Inventory Issue | P9: 1 | Q9: 1
A10: 77K98EC | B10: New Installations, Isolated Clients, Inventory Issue | P10: 1 | Q10: 1
A11: 77L35EC#ACJ | B11: New Installations, Isolated Clients, Inventory Issue | P11: 1 | Q11: 1
A12: 800 G5 DM DP PC I7 9700 | B12: New Installations, Isolated Clients, Inventory Issue | G12: 1 | Q12: 1
A13: Agile_S | B13: New Installations, Isolated Clients, Inventory Issue | P13: 1 | Q13: 1
A14: APC910 | B14: New Installations, Isolated Clients, Inventory Issue | P14: 3 | Q14: 3
A15: CRB-2 | B15: New Installations, Isolated Clients, Inventory Issue | P15: 1 | Q15: 1
A16: Dell Pro Max 16 Plus MB16250 | B16: New Installations, Isolated Clients, Inventory Issue | P16: 1 | Q16: 1
A17: Dell Pro Micro QCM1250 | B17: New Installations, Isolated Clients, Inventory Issue | P17: 1 | Q17: 1
A18: G9L79UP | B18: New Installations, Isolated Clients, Inventory Issue | P18: 1 | Q18: 1
A19: HP 800G3ED TWR I76700 | B19: New Installations, Isolated Clients, Inventory Issue | E19: 1 | Q19: 1
A20: HP Compaq 8000 Elite CMT PC | B20: New Installations, Isolated Clients, Inventory Issue | P20: 1 | Q20: 1
A21: HP Elite | B21: New Installations, Isolated Clients, Inventory Issue | P21: 1 | Q21: 1
A22: HP Pavilion Gaming Laptop | B22: New Installations, Isolated Clients, Inventory Issue | P22: 1 | Q22: 1
A23: Intense-PC2 (IPC2) | B23: New Installations, Isolated Clients, Inventory Issue | P23: 2 | Q23: 2
A24: Intense-PC2-BRW (IPC2) | B24: New Installations, Isolated Clients, Inventory Issue | P24: 2 | Q24: 2
A25: MS-CF02 | B25: New Installations, Isolated Clients, Inventory Issue | P25: 2 | Q25: 2
A26: NULL | B26: New Installations, Isolated Clients, Inventory Issue | P26: 1794 | Q26: 1794
A27: PPC2200 | B27: New Installations, Isolated Clients, Inventory Issue | P27: 10 | Q27: 10
A28: SAA8 | B28: New Installations, Isolated Clients, Inventory Issue | P28: 2 | Q28: 2
A29: Standard PC (Q35 + ICH9, 2009) | B29: New Installations, Isolated Clients, Inventory Issue | P29: 1 | Q29: 1
A30: SYS-7048GR-TR | B30: New Installations, Isolated Clients, Inventory Issue | P30: 2 | Q30: 2
A31: System Product Name | B31: New Installations, Isolated Clients, Inventory Issue | P31: 2 | Q31: 2
A32: X11SSV-Q | B32: New Installations, Isolated Clients, Inventory Issue | P32: 1 | Q32: 1
B33: New Installations, Isolated Clients, Inventory Issue Total | E33: 1 | G33: 1 | P33: 1840 | Q33: 1842
A34: 21KYS8WK00 | B34: Profile 1 Customized, Standard User 14” screen and +16gb of RAM | P34: 1 | Q34: 1
A35: 21KYS8WK02 | B35: Profile 1 Customized, Standard User 14” screen and +16gb of RAM | P35: 1 | Q35: 1
A36: 21KYS8WK03 | B36: Profile 1 Customized, Standard User 14” screen and +16gb of RAM | P36: 1 | Q36: 1
A37: 21QBS18T00 | B37: Profile 1 Customized, Standard User 14” screen and +16gb of RAM | P37: 1 | Q37: 1
A38: HP EliteBook 8 G1i 14 inch Notebook AI PC | B38: Profile 1 Customized, Standard User 14” screen and +16gb of RAM | O38: 518 | Q38: 518
A39: HP EliteBook 840 14 inch G10 Notebook PC | B39: Profile 1 Customized, Standard User 14” screen and +16gb of RAM | M39: 1601 | Q39: 1601
A40: HP EliteBook 840 14 inch G10 Notebook PC hp | B40: Profile 1 Customized, Standard User 14” screen and +16gb of RAM | M40: 1 | Q40: 1
A41: HP EliteBook 840 14 inch G11 Notebook PC | B41: Profile 1 Customized, Standard User 14” screen and +16gb of RAM | N41: 2260 | P41: 1 | Q41: 2261
A42: HP EliteBook 840 14 inch G9 Notebook PC | B42: Profile 1 Customized, Standard User 14” screen and +16gb of RAM | L42: 1072 | Q42: 1072
...
